Workbook
Name _03_33_C5_C6: #REF!
Name _03_33_C5_C6: #REF!
Name _03_33_C5_C6: #REF!
Name _41_42_43_44: #REF!
Name _41_42_43_44: #REF!
Name _41_42_43_44: #REF!
Name _ASP2: [1]dis02!$AW$4
Name _ASP2: [2]dis02!$AW$4
Name _dec06: [3]globals!$C$15
Name _jun06: [3]globals!$C$9
Name _sep06: [3]globals!$C$12
Name A: #REF!
Name A: #REF!
Name A: #REF!
Name A: #REF!
Name AB: #REF!
Name AB: #REF!
Name ac: #REF!
Name ac: #REF!
Name accpd: [3]newavbsum!$AZ$9:$BI$9
Name actshortpd: [3]newavbsum!$BL$4:$BT$4
Name ADD: [4]Globals!$D$9:$D$9
Name ASP: [1]dis02!$AW$3
Name ASP: [2]dis02!$AW$3
Name B: #REF!
Name B: #REF!
Name B: #REF!
Name B: #REF!
Name b4start: #REF!
Name b4start: #REF!
Name b4start: #REF!
Name Bacs: '[1]CWL 2005'!$BC$453
Name Bacs: '[2]CWL 2005'!$BC$453
Name BBDEC95TOTAL: #REF!
Name BBDEC95TOTAL: #REF!
Name BBDEC95TOTAL: #REF!
Name BLAX_VAT: #REF!
Name BLAX_VAT: #REF!
Name BLAX_VAT: #REF!
Name bonusni: #REF!
Name bonusni: #REF!
Name budshortpd: [3]newavbsum!$T$4:$AB$4
Name CABOTPLACERT2_VAT: #REF!
Name CABOTPLACERT2_VAT: #REF!
Name CABOTPLACERT2_VAT: #REF!
Name CANADAPLACE_VAT: #REF!
Name CANADAPLACE_VAT: #REF!
Name CANADAPLACE_VAT: #REF!
Name CANCEL: #REF!
Name CANCEL: #REF!
Name CANCEL: #REF!
Name CASP: [1]dis02!$AW$2
Name CASP: [2]dis02!$AW$2
Name CoName: [5]Front!$B$4:$B$305
Name CoNo: [5]Front!$A$4:$A$305
Name CPL_VAT: #REF!
Name CPL_VAT: #REF!
Name CPL_VAT: #REF!
Name CPRUNITTRUST_VAT: #REF!
Name CPRUNITTRUST_VAT: #REF!

Sheet Instructions
B2: Please fill in the tab 'FinCharges'
B4: Please note:
A5: 1 | B5: All Yellow headed columns on Fincharges to be populated
A6: 2 | B6: The Request Reference is a name chosen for your records with a maximum of 24 characters (eg. your initials and a sequential number (SL 001), department, intial and sequential number (Tax SN 001), subject matter etc…)
A7: 3 | B7: Post Month & GL account need to be populated
A8: 4 | B8: If Recoverability and/or Budget options pop up, you need to pick one option only & populate the cell
A9: 5 | B9: VAT Rate is to be selected from a drop down menu
A10: 6 | B10: Payment Method must be selected froma drop dwon menu - Cheque for IC Offset or EFT for Cash settlement (Yardi default bank accounts associated with owners will be used)
A11: 7 | B11: Coding for Payables - input format should be GLAccount.Recoverability.Schedule - if GL account only provided GEN wil be applied by Yardi automatically
A12: 8 | B12: Add backup and approvals worksheets
A13: 9 | B13: If uploading FinCharges yourself make sure to delete content of all unused rows
B16: Link to useful information:
B18: Yardi - Useful Documents - All Documents

Sheet Instruction
B2: Weekly update guide
B4: Step 1: Membership Invoices
C5: 1.Clear current data from row 5 onwards
C6: 2.Copy from row 5 onwards, make sure it's unmerged before you paste the data
B8: Step 2: Power Query table tab
C9: 1.Right-click then click refresh
C10: 2. delete all the total columns
B12: Step 3: Upload tab
C13: 1.drag the formulas down | I13: Upload tab
C14: 2.sense check to make sure all values come back as True | H14: >>>
B16: Step 4: ETL
C17: 1.Drag all the formulas down, if needed
I20: Membership tab

Sheet ETL
A1: Fincharges | B1: Property | D1: Charge to | E1: Charge Code | F1: Net Amt | G1: Date | H1: Post Month | I1: Account | J1: AR Account | K1: Line Notes | M1: Reference | P1: Recoverability | Q1: Schedule | R1: Owner (Landlord) | S1: Business Segment | T1: Person | U1: Intercompany | Y1: Budget | AB1: Net Amount | AC1: Currency | AH1: Vat Amt | AJ1: From Date | AK1: To Date | AM1: Tran Type | AN1: Tax Rate | AP1: Payment Method | AQ1: Coding for Payables | AS1: Job | AT1: Category | AU1: Costcode | AV1: Contract | BE1: Display Type
A2: TRANNUM | B2: PROPERTY | C2: REF_PROPERTY_ID | D2: PERSON | E2: OFFSET | F2: AMOUNT | G2: DATE | H2: POSTMONTH | I2: ACCOUNT | J2: ACCRUAL | K2: NOTES | L2: USERDEFINEDFIELD1 | M2: REF | N2: DOCUMENTSEQUENCENUMBER | O2: UNIT | P2: SEGMENT1 | Q2: SEGMENT2 | R2: SEGMENT3 | S2: SEGMENT4 | T2: SEGMENT5 | U2: SEGMENT6 | V2: SEGMENT7 | W2: SEGMENT8 | X2: SEGMENT9 | Y2: SEGMENT10 | Z2: SEGMENT11 | AA2: SEGMENT12 | AB2: TRANAMOUNT | AC2: TRANCURRENCYID | AD2: EXCHANGERATE | AE2: EXCHANGERATEDATE | AF2: EXCHANGERATE2 | AG2: EXCHANGERATEDATE2 | AH2: TAXAMOUNT1 | AI2: TAXAMOUNT2 | AJ2: FROMDATE | AK2: TODATE | AL2: TAXPOINTDATE | AM2: VATTRANTYPEID | AN2: VATRATEID | AO2: TRANDATE | AP2: INTERNATIONALPAYMENTTYPE | AQ2: NOTES2 | AR2: FUNCTIONALCURRENCYAMOUNT | AS2: JOB | AT2: CATEGORY | AU2: CostCode | AV2: Contract | AW2: TRANFIELD1 | AX2: TRANFIELD2 | AY2: TRANFIELD3 | AZ2: TRANFIELD4 | BA2: TRANFIELD5 | BB2: TRANFIELD6 | BC2: TRANFIELD7 | BD2: TRANFIELD8 | BE2: DISPLAYTYPE
A3: 1 | B3: c0et | D3: ='Upload tab'!A3 -> c0000935 | E3: misc | F3: ='Upload tab'!B3 -> 440 | G3: =TODAY() -> 46070 | H3: =G3 -> 46070 | I3: =SUBSTITUTE('Upload tab'!E3,"-","") -> 42113011 | J3: 12212311 | K3: ='Upload tab'!F3 -> L3924638-JEB ENGINEERING SERVICES LLP | N3: 1 | P3: GEN | Y3: Lvl39 | AB3: =F3 -> 440 | AC3: gbp | AH3: =IF(AN3="UKSTD20",F3*0.2,(IF(AN3="UKred5",F3*0.05,0))) -> 0 | AJ3: ='Upload tab'!H3 -> 01/02/2025 | AK3: ='Upload tab'!I3 -> 28/02/2026 | AM3: =_xlfn.IFNA(_xlfn.XLOOKUP(AN3,VAT!$A$1:$A$10,VAT!$D$1:$D$10),"") | AN3: {=_xlfn.IFNA(_xlfn.IFS(LEFT(M3,4)="L39N","outside",LEFT(M3,3)="L39","ukstd20"),"")} | AO3: 45869 | AP3: EFT | BE3: STANDARD CHARGE DISPLAY TYPE | CB3: 0 | CC3: 0 | CD3: 0
AN4: {=_xlfn.IFNA(_xlfn.IFS(LEFT(M4,4)="L39N","outside",LEFT(M4,3)="L39","ukstd20"),"")}
AN6: {=_xlfn.IFNA(_xlfn.IFS(LEFT(M6,4)="L39N","outside",LEFT(M6,3)="L39","ukstd20"),"")}
AN7: {=_xlfn.IFNA(_xlfn.IFS(LEFT(M7,4)="L39N","outside",LEFT(M7,3)="L39","ukstd20"),"")}
AN8: {=_xlfn.IFNA(_xlfn.IFS(LEFT(M8,4)="L39N","outside",LEFT(M8,3)="L39","ukstd20"),"")}
AN9: {=_xlfn.IFNA(_xlfn.IFS(LEFT(M9,4)="L39N","outside",LEFT(M9,3)="L39","ukstd20"),"")}
AN10: {=_xlfn.IFNA(_xlfn.IFS(LEFT(M10,4)="L39N","outside",LEFT(M10,3)="L39","ukstd20"),"")}
AN11: {=_xlfn.IFNA(_xlfn.IFS(LEFT(M11,4)="L39N","outside",LEFT(M11,3)="L39","ukstd20"),"")}
AN12: {=_xlfn.IFNA(_xlfn.IFS(LEFT(M12,4)="L39N","outside",LEFT(M12,3)="L39","ukstd20"),"")}
AN13: {=_xlfn.IFNA(_xlfn.IFS(LEFT(M13,4)="L39N","outside",LEFT(M13,3)="L39","ukstd20"),"")}
AN14: {=_xlfn.IFNA(_xlfn.IFS(LEFT(M14,4)="L39N","outside",LEFT(M14,3)="L39","ukstd20"),"")}
AN15: {=_xlfn.IFNA(_xlfn.IFS(LEFT(M15,4)="L39N","outside",LEFT(M15,3)="L39","ukstd20"),"")}
AN16: {=_xlfn.IFNA(_xlfn.IFS(LEFT(M16,4)="L39N","outside",LEFT(M16,3)="L39","ukstd20"),"")}
... AN221: {=_xlfn.IFNA(_xlfn.IFS(LEFT(M221,4)="L39N","outside",LEFT(M221,3)="L39","ukstd20"),"")}

Sheet Upload tab
A1: Charge to | B1: Net Amt | C1: Date | D1: Post Month | E1: Account | F1: Line Notes | G1: Reference | H1: From Date | I1: To Date
A2: PERSON | B2: AMOUNT | C2: DATE | D2: POSTMONTH | E2: ACCOUNT | F2: NOTES | G2: REF | H2: FROMDATE | I2: TODATE | K2: Nominal Code | L2: Upload tab | N2: ETL
A3: =IF(LEFT(F3,4)="L39N","c0001836",IF(LEFT(F3,3)="L24","c0000008",IF(LEFT(F3,3)="L39","c0000935",""))) -> c0000935 | B3: ='Power Query Table'!P2 -> 440 | C3: =TODAY() -> 46070 | D3: =TODAY() -> 46070 | E3: =LEFT('Power Query Table'!O2,9) -> 4211-3011 | F3: =CONCATENATE('Power Query Table'!A2, "-","",'Power Query Table'!B2) -> L3924638-JEB ENGINEERING SERVICES LLP | G3: =IF(LEFT(F3,4)="L39N",LEFT(F3,9),LEFT(F3,8)) -> L3924638 | H3: =TEXT(DATE(2025,MONTH(TODAY()),1),"dd/mm/yyyy") -> 01/02/2025 | I3: =TEXT(EOMONTH(TODAY(),0),"dd/mm/yyyy") -> 28/02/2026 | K3: {=_xlfn.UNIQUE(E:E,FALSE,FALSE)} -> Account
A4: =IF(LEFT(F4,4)="L39N","c0001836",IF(LEFT(F4,3)="L24","c0000008",IF(LEFT(F4,3)="L39","c0000935",""))) -> #REF! | B4: ='Power Query Table'!#REF! -> #REF! | C4: =TODAY() -> 46070 | D4: =TODAY() -> 46070 | E4: =LEFT('Power Query Table'!#REF!,9) -> #REF! | F4: =CONCATENATE('Power Query Table'!#REF!, "-","",'Power Query Table'!#REF!) -> #REF! | G4: =IF(LEFT(F4,4)="L39N",LEFT(F4,9),LEFT(F4,8)) -> #REF! | H4: =TEXT(DATE(2025,MONTH(TODAY()),1),"dd/mm/yyyy") -> 01/02/2025 | I4: =TEXT(EOMONTH(TODAY(),0),"dd/mm/yyyy") -> 28/02/2026 | K4: ACCOUNT
A5: =IF(LEFT(F5,4)="L39N","c0001836",IF(LEFT(F5,3)="L24","c0000008",IF(LEFT(F5,3)="L39","c0000935",""))) -> #REF! | B5: ='Power Query Table'!#REF! -> #REF! | C5: =TODAY() -> 46070 | D5: =TODAY() -> 46070 | E5: =LEFT('Power Query Table'!#REF!,9) -> #REF! | F5: =CONCATENATE('Power Query Table'!#REF!, "-","",'Power Query Table'!#REF!) -> #REF! | G5: =IF(LEFT(F5,4)="L39N",LEFT(F5,9),LEFT(F5,8)) -> #REF! | H5: =TEXT(DATE(2025,MONTH(TODAY()),1),"dd/mm/yyyy") -> 01/02/2025 | I5: =TEXT(EOMONTH(TODAY(),0),"dd/mm/yyyy") -> 28/02/2026 | K5: 4211-3011 | L5: =SUMIFS(B:B,E:E,K5) -> 440 | M5: =SUBSTITUTE(K5,"-","") -> 42113011 | N5: =SUMIFS(ETL!F:F,ETL!I:I,'Upload tab'!M5) -> 440 | O5: =L5=N5 -> TRUE
A6: =IF(LEFT(F6,4)="L39N","c0001836",IF(LEFT(F6,3)="L24","c0000008",IF(LEFT(F6,3)="L39","c0000935",""))) -> #REF! | B6: ='Power Query Table'!#REF! -> #REF! | C6: =TODAY() -> 46070 | D6: =TODAY() -> 46070 | E6: =LEFT('Power Query Table'!#REF!,9) -> #REF! | F6: =CONCATENATE('Power Query Table'!#REF!, "-","",'Power Query Table'!#REF!) -> #REF! | G6: =IF(LEFT(F6,4)="L39N",LEFT(F6,9),LEFT(F6,8)) -> #REF! | H6: =TEXT(DATE(2025,MONTH(TODAY()),1),"dd/mm/yyyy") -> 01/02/2025 | I6: =TEXT(EOMONTH(TODAY(),0),"dd/mm/yyyy") -> 28/02/2026 | K6: #REF! | L6: =SUMIFS(B:B,E:E,K6) -> #REF! | M6: =SUBSTITUTE(K6,"-","") -> #REF! | N6: =SUMIFS(ETL!F:F,ETL!I:I,'Upload tab'!M6) -> 0 | O6: =L6=N6 -> #REF!
A7: =IF(LEFT(F7,4)="L39N","c0001836",IF(LEFT(F7,3)="L24","c0000008",IF(LEFT(F7,3)="L39","c0000935",""))) -> #REF! | B7: ='Power Query Table'!#REF! -> #REF! | C7: =TODAY() -> 46070 | D7: =TODAY() -> 46070 | E7: =LEFT('Power Query Table'!#REF!,9) -> #REF! | F7: =CONCATENATE('Power Query Table'!#REF!, "-","",'Power Query Table'!#REF!) -> #REF! | G7: =IF(LEFT(F7,4)="L39N",LEFT(F7,9),LEFT(F7,8)) -> #REF! | H7: =TEXT(DATE(2025,MONTH(TODAY()),1),"dd/mm/yyyy") -> 01/02/2025 | I7: =TEXT(EOMONTH(TODAY(),0),"dd/mm/yyyy") -> 28/02/2026 | K7: 0 | L7: =SUMIFS(B:B,E:E,K7) -> 0 | M7: =SUBSTITUTE(K7,"-","") -> 0 | N7: =SUMIFS(ETL!F:F,ETL!I:I,'Upload tab'!M7) -> 0 | O7: =L7=N7 -> TRUE
A8: =IF(LEFT(F8,4)="L39N","c0001836",IF(LEFT(F8,3)="L24","c0000008",IF(LEFT(F8,3)="L39","c0000935",""))) -> #REF! | B8: ='Power Query Table'!#REF! -> #REF! | C8: =TODAY() -> 46070 | D8: =TODAY() -> 46070 | E8: =LEFT('Power Query Table'!#REF!,9) -> #REF! | F8: =CONCATENATE('Power Query Table'!#REF!, "-","",'Power Query Table'!#REF!) -> #REF! | G8: =IF(LEFT(F8,4)="L39N",LEFT(F8,9),LEFT(F8,8)) -> #REF! | H8: =TEXT(DATE(2025,MONTH(TODAY()),1),"dd/mm/yyyy") -> 01/02/2025 | I8: =TEXT(EOMONTH(TODAY(),0),"dd/mm/yyyy") -> 28/02/2026 | L8: =SUMIFS(B:B,E:E,K8) -> 0 | M8: =SUBSTITUTE(K8,"-","") | N8: =SUMIFS(ETL!F:F,ETL!I:I,'Upload tab'!M8) -> 0 | O8: =L8=N8 -> TRUE
A9: =IF(LEFT(F9,4)="L39N","c0001836",IF(LEFT(F9,3)="L24","c0000008",IF(LEFT(F9,3)="L39","c0000935",""))) -> #REF! | B9: ='Power Query Table'!#REF! -> #REF! | C9: =TODAY() -> 46070 | D9: =TODAY() -> 46070 | E9: =LEFT('Power Query Table'!#REF!,9) -> #REF! | F9: =CONCATENATE('Power Query Table'!#REF!, "-","",'Power Query Table'!#REF!) -> #REF! | G9: =IF(LEFT(F9,4)="L39N",LEFT(F9,9),LEFT(F9,8)) -> #REF! | H9: =TEXT(DATE(2025,MONTH(TODAY()),1),"dd/mm/yyyy") -> 01/02/2025 | I9: =TEXT(EOMONTH(TODAY(),0),"dd/mm/yyyy") -> 28/02/2026 | L9: =SUMIFS(B:B,E:E,K9) -> 0 | M9: =SUBSTITUTE(K9,"-","") | N9: =SUMIFS(ETL!F:F,ETL!I:I,'Upload tab'!M9) -> 0 | O9: =L9=N9 -> TRUE
A10: =IF(LEFT(F10,4)="L39N","c0001836",IF(LEFT(F10,3)="L24","c0000008",IF(LEFT(F10,3)="L39","c0000935",""))) -> #REF! | B10: ='Power Query Table'!#REF! -> #REF! | C10: =TODAY() -> 46070 | D10: =TODAY() -> 46070 | E10: =LEFT('Power Query Table'!#REF!,9) -> #REF! | F10: =CONCATENATE('Power Query Table'!#REF!, "-","",'Power Query Table'!#REF!) -> #REF! | G10: =IF(LEFT(F10,4)="L39N",LEFT(F10,9),LEFT(F10,8)) -> #REF! | H10: =TEXT(DATE(2025,MONTH(TODAY()),1),"dd/mm/yyyy") -> 01/02/2025 | I10: =TEXT(EOMONTH(TODAY(),0),"dd/mm/yyyy") -> 28/02/2026 | L10: =SUMIFS(B:B,E:E,K10) -> 0 | M10: =SUBSTITUTE(K10,"-","") | N10: =SUMIFS(ETL!F:F,ETL!I:I,'Upload tab'!M10) -> 0 | O10: =L10=N10 -> TRUE
A11: =IF(LEFT(F11,4)="L39N","c0001836",IF(LEFT(F11,3)="L24","c0000008",IF(LEFT(F11,3)="L39","c0000935",""))) -> #REF! | B11: ='Power Query Table'!#REF! -> #REF! | C11: =TODAY() -> 46070 | D11: =TODAY() -> 46070 | E11: =LEFT('Power Query Table'!#REF!,9) -> #REF! | F11: =CONCATENATE('Power Query Table'!#REF!, "-","",'Power Query Table'!#REF!) -> #REF! | G11: =IF(LEFT(F11,4)="L39N",LEFT(F11,9),LEFT(F11,8)) -> #REF! | H11: =TEXT(DATE(2025,MONTH(TODAY()),1),"dd/mm/yyyy") -> 01/02/2025 | I11: =TEXT(EOMONTH(TODAY(),0),"dd/mm/yyyy") -> 28/02/2026 | L11: =SUMIFS(B:B,E:E,K11) -> 0 | M11: =SUBSTITUTE(K11,"-","") | N11: =SUMIFS(ETL!F:F,ETL!I:I,'Upload tab'!M11) -> 0 | O11: =L11=N11 -> TRUE
A12: =IF(LEFT(F12,4)="L39N","c0001836",IF(LEFT(F12,3)="L24","c0000008",IF(LEFT(F12,3)="L39","c0000935",""))) -> #REF! | B12: ='Power Query Table'!#REF! -> #REF! | C12: =TODAY() -> 46070 | D12: =TODAY() -> 46070 | E12: =LEFT('Power Query Table'!#REF!,9) -> #REF! | F12: =CONCATENATE('Power Query Table'!#REF!, "-","",'Power Query Table'!#REF!) -> #REF! | G12: =IF(LEFT(F12,4)="L39N",LEFT(F12,9),LEFT(F12,8)) -> #REF! | H12: =TEXT(DATE(2025,MONTH(TODAY()),1),"dd/mm/yyyy") -> 01/02/2025 | I12: =TEXT(EOMONTH(TODAY(),0),"dd/mm/yyyy") -> 28/02/2026 | L12: =SUMIFS(B:B,E:E,K12) -> 0 | M12: =SUBSTITUTE(K12,"-","") | N12: =SUMIFS(ETL!F:F,ETL!I:I,'Upload tab'!M12) -> 0 | O12: =L12=N12 -> TRUE
A13: =IF(LEFT(F13,4)="L39N","c0001836",IF(LEFT(F13,3)="L24","c0000008",IF(LEFT(F13,3)="L39","c0000935",""))) -> #REF! | B13: ='Power Query Table'!#REF! -> #REF! | C13: =TODAY() -> 46070 | D13: =TODAY() -> 46070 | E13: =LEFT('Power Query Table'!#REF!,9) -> #REF! | F13: =CONCATENATE('Power Query Table'!#REF!, "-","",'Power Query Table'!#REF!) -> #REF! | G13: =IF(LEFT(F13,4)="L39N",LEFT(F13,9),LEFT(F13,8)) -> #REF! | H13: =TEXT(DATE(2025,MONTH(TODAY()),1),"dd/mm/yyyy") -> 01/02/2025 | I13: =TEXT(EOMONTH(TODAY(),0),"dd/mm/yyyy") -> 28/02/2026 | L13: =SUMIFS(B:B,E:E,K13) -> 0 | M13: =SUBSTITUTE(K13,"-","") | N13: =SUMIFS(ETL!F:F,ETL!I:I,'Upload tab'!M13) -> 0 | O13: =L13=N13 -> TRUE
A14: =IF(LEFT(F14,4)="L39N","c0001836",IF(LEFT(F14,3)="L24","c0000008",IF(LEFT(F14,3)="L39","c0000935",""))) -> #REF! | B14: ='Power Query Table'!#REF! -> #REF! | C14: =TODAY() -> 46070 | D14: =TODAY() -> 46070 | E14: =LEFT('Power Query Table'!#REF!,9) -> #REF! | F14: =CONCATENATE('Power Query Table'!#REF!, "-","",'Power Query Table'!#REF!) -> #REF! | G14: =IF(LEFT(F14,4)="L39N",LEFT(F14,9),LEFT(F14,8)) -> #REF! | H14: =TEXT(DATE(2025,MONTH(TODAY()),1),"dd/mm/yyyy") -> 01/02/2025 | I14: =TEXT(EOMONTH(TODAY(),0),"dd/mm/yyyy") -> 28/02/2026 | L14: =SUMIFS(B:B,E:E,K14) -> 0 | M14: =SUBSTITUTE(K14,"-","") | N14: =SUMIFS(ETL!F:F,ETL!I:I,'Upload tab'!M14) -> 0 | O14: =L14=N14 -> TRUE
A15: =IF(LEFT(F15,4)="L39N","c0001836",IF(LEFT(F15,3)="L24","c0000008",IF(LEFT(F15,3)="L39","c0000935",""))) -> #REF! | B15: ='Power Query Table'!#REF! -> #REF! | C15: =TODAY() -> 46070 | D15: =TODAY() -> 46070 | E15: =LEFT('Power Query Table'!#REF!,9) -> #REF! | F15: =CONCATENATE('Power Query Table'!#REF!, "-","",'Power Query Table'!#REF!) -> #REF! | G15: =IF(LEFT(F15,4)="L39N",LEFT(F15,9),LEFT(F15,8)) -> #REF! | H15: =TEXT(DATE(2025,MONTH(TODAY()),1),"dd/mm/yyyy") -> 01/02/2025 | I15: =TEXT(EOMONTH(TODAY(),0),"dd/mm/yyyy") -> 28/02/2026 | L15: =SUMIFS(B:B,E:E,K15) -> 0 | M15: =SUBSTITUTE(K15,"-","") | N15: =SUMIFS(ETL!F:F,ETL!I:I,'Upload tab'!M15) -> 0 | O15: =L15=N15 -> TRUE
A16: =IF(LEFT(F16,4)="L39N","c0001836",IF(LEFT(F16,3)="L24","c0000008",IF(LEFT(F16,3)="L39","c0000935",""))) -> #REF! | B16: ='Power Query Table'!#REF! -> #REF! | C16: =TODAY() -> 46070 | D16: =TODAY() -> 46070 | E16: =LEFT('Power Query Table'!#REF!,9) -> #REF! | F16: =CONCATENATE('Power Query Table'!#REF!, "-","",'Power Query Table'!#REF!) -> #REF! | G16: =IF(LEFT(F16,4)="L39N",LEFT(F16,9),LEFT(F16,8)) -> #REF! | H16: =TEXT(DATE(2025,MONTH(TODAY()),1),"dd/mm/yyyy") -> 01/02/2025 | I16: =TEXT(EOMONTH(TODAY(),0),"dd/mm/yyyy") -> 28/02/2026 | L16: =SUMIFS(B:B,E:E,K16) -> 0 | M16: =SUBSTITUTE(K16,"-","") | N16: =SUMIFS(ETL!F:F,ETL!I:I,'Upload tab'!M16) -> 0 | O16: =L16=N16 -> TRUE
A17: =IF(LEFT(F17,4)="L39N","c0001836",IF(LEFT(F17,3)="L24","c0000008",IF(LEFT(F17,3)="L39","c0000935",""))) -> #REF! | B17: ='Power Query Table'!#REF! -> #REF! | C17: =TODAY() -> 46070 | D17: =TODAY() -> 46070 | E17: =LEFT('Power Query Table'!#REF!,9) -> #REF! | F17: =CONCATENATE('Power Query Table'!#REF!, "-","",'Power Query Table'!#REF!) -> #REF! | G17: =IF(LEFT(F17,4)="L39N",LEFT(F17,9),LEFT(F17,8)) -> #REF! | H17: =TEXT(DATE(2025,MONTH(TODAY()),1),"dd/mm/yyyy") -> 01/02/2025 | I17: =TEXT(EOMONTH(TODAY(),0),"dd/mm/yyyy") -> 28/02/2026 | L17: =SUMIFS(B:B,E:E,K17) -> 0 | M17: =SUBSTITUTE(K17,"-","") | N17: =SUMIFS(ETL!F:F,ETL!I:I,'Upload tab'!M17) -> 0 | O17: =L17=N17 -> TRUE
A18: =IF(LEFT(F18,4)="L39N","c0001836",IF(LEFT(F18,3)="L24","c0000008",IF(LEFT(F18,3)="L39","c0000935",""))) -> #REF! | B18: ='Power Query Table'!#REF! -> #REF! | C18: =TODAY() -> 46070 | D18: =TODAY() -> 46070 | E18: =LEFT('Power Query Table'!#REF!,9) -> #REF! | F18: =CONCATENATE('Power Query Table'!#REF!, "-","",'Power Query Table'!#REF!) -> #REF! | G18: =IF(LEFT(F18,4)="L39N",LEFT(F18,9),LEFT(F18,8)) -> #REF! | H18: =TEXT(DATE(2025,MONTH(TODAY()),1),"dd/mm/yyyy") -> 01/02/2025 | I18: =TEXT(EOMONTH(TODAY(),0),"dd/mm/yyyy") -> 28/02/2026 | L18: =SUMIFS(B:B,E:E,K18) -> 0 | M18: =SUBSTITUTE(K18,"-","") | N18: =SUMIFS(ETL!F:F,ETL!I:I,'Upload tab'!M18) -> 0 | O18: =L18=N18 -> TRUE
A19: =IF(LEFT(F19,4)="L39N","c0001836",IF(LEFT(F19,3)="L24","c0000008",IF(LEFT(F19,3)="L39","c0000935",""))) -> #REF! | B19: ='Power Query Table'!#REF! -> #REF! | C19: =TODAY() -> 46070 | D19: =TODAY() -> 46070 | E19: =LEFT('Power Query Table'!#REF!,9) -> #REF! | F19: =CONCATENATE('Power Query Table'!#REF!, "-","",'Power Query Table'!#REF!) -> #REF! | G19: =IF(LEFT(F19,4)="L39N",LEFT(F19,9),LEFT(F19,8)) -> #REF! | H19: =TEXT(DATE(2025,MONTH(TODAY()),1),"dd/mm/yyyy") -> 01/02/2025 | I19: =TEXT(EOMONTH(TODAY(),0),"dd/mm/yyyy") -> 28/02/2026 | L19: =SUMIFS(B:B,E:E,K19) -> 0 | M19: =SUBSTITUTE(K19,"-","") | N19: =SUMIFS(ETL!F:F,ETL!I:I,'Upload tab'!M19) -> 0 | O19: =L19=N19 -> TRUE
... A28: =IF(LEFT(F28,4)="L39N","c0001836",IF(LEFT(F28,3)="L24","c0000008",IF(LEFT(F28,3)="L39","c0000935",""))) -> #REF! | B28: ='Power Query Table'!#REF! -> #REF! | C28: =TODAY() -> 46070 | D28: =TODAY() -> 46070 | E28: =LEFT('Power Query Table'!#REF!,9) -> #REF! | F28: =CONCATENATE('Power Query Table'!#REF!, "-","",'Power Query Table'!#REF!) -> #REF! | G28: =IF(LEFT(F28,4)="L39N",LEFT(F28,9),LEFT(F28,8)) -> #REF! | H28: =TEXT(DATE(2025,MONTH(TODAY()),1),"dd/mm/yyyy") -> 01/02/2025 | I28: =TEXT(EOMONTH(TODAY(),0),"dd/mm/yyyy") -> 28/02/2026 | L28: =SUMIFS(B:B,E:E,K28) -> 0 | M28: =SUBSTITUTE(K28,"-","") | N28: =SUMIFS(ETL!F:F,ETL!I:I,'Upload tab'!M28) -> 0 | O28: =L28=N28 -> TRUE
A29: =IF(LEFT(F29,4)="L39N","c0001836",IF(LEFT(F29,3)="L24","c0000008",IF(LEFT(F29,3)="L39","c0000935",""))) -> #REF! | B29: ='Power Query Table'!#REF! -> #REF! | C29: =TODAY() -> 46070 | D29: =TODAY() -> 46070 | E29: =LEFT('Power Query Table'!#REF!,9) -> #REF! | F29: =CONCATENATE('Power Query Table'!#REF!, "-","",'Power Query Table'!#REF!) -> #REF! | G29: =IF(LEFT(F29,4)="L39N",LEFT(F29,9),LEFT(F29,8)) -> #REF! | H29: =TEXT(DATE(2025,MONTH(TODAY()),1),"dd/mm/yyyy") -> 01/02/2025 | I29: =TEXT(EOMONTH(TODAY(),0),"dd/mm/yyyy") -> 28/02/2026 | K29: Total | L29: =SUM(L5:L10) -> #REF! | M29: =SUBSTITUTE(K29,"-","") -> Total | N29: =SUM(N5:N10) -> 440 | O29: =L29=N29 -> #REF!
A30: =IF(LEFT(F30,4)="L39N","c0001836",IF(LEFT(F30,3)="L24","c0000008",IF(LEFT(F30,3)="L39","c0000935",""))) -> #REF! | B30: ='Power Query Table'!#REF! -> #REF! | C30: =TODAY() -> 46070 | D30: =TODAY() -> 46070 | E30: =LEFT('Power Query Table'!#REF!,9) -> #REF! | F30: =CONCATENATE('Power Query Table'!#REF!, "-","",'Power Query Table'!#REF!) -> #REF! | G30: =IF(LEFT(F30,4)="L39N",LEFT(F30,9),LEFT(F30,8)) -> #REF! | H30: =TEXT(DATE(2025,MONTH(TODAY()),1),"dd/mm/yyyy") -> 01/02/2025 | I30: =TEXT(EOMONTH(TODAY(),0),"dd/mm/yyyy") -> 28/02/2026
K33: Nominal Code | L33: Upload tab | M33: Membership
K34: {=_xlfn.UNIQUE('Power Query Table'!O:O,FALSE,FALSE)} -> Attribute
K35: 4211-3011 - L39 Hot Desk Membership (2024) | L35: =SUMIFS('Power Query Table'!P:P,'Power Query Table'!O:O,'Upload tab'!K35) -> 440 | M35: =INDEX('Membership invoices'!$7:$7,MATCH('Upload tab'!K35,'Membership invoices'!$5:$5,0)) -> #N/A | N35: =L35=M35 -> #N/A
K36: 0 | L36: =SUMIFS('Power Query Table'!P:P,'Power Query Table'!O:O,'Upload tab'!K36) -> 0 | M36: =INDEX('Membership invoices'!$32:$32,MATCH('Upload tab'!K36,'Membership invoices'!$5:$5,0)) -> #N/A | N36: =L36=M36 -> #N/A
L37: =SUMIFS('Power Query Table'!P:P,'Power Query Table'!O:O,'Upload tab'!K37) -> 0 | M37: =INDEX('Membership invoices'!$32:$32,MATCH('Upload tab'!K37,'Membership invoices'!$5:$5,0)) -> #N/A | N37: =L37=M37 -> #N/A
L38: =SUMIFS('Power Query Table'!P:P,'Power Query Table'!O:O,'Upload tab'!K38) -> 0 | M38: =INDEX('Membership invoices'!$32:$32,MATCH('Upload tab'!K38,'Membership invoices'!$5:$5,0)) -> #N/A | N38: =L38=M38 -> #N/A
L39: =SUMIFS('Power Query Table'!P:P,'Power Query Table'!O:O,'Upload tab'!K39) -> 0 | M39: =INDEX('Membership invoices'!$32:$32,MATCH('Upload tab'!K39,'Membership invoices'!$5:$5,0)) -> #N/A | N39: =L39=M39 -> #N/A
L40: =SUMIFS('Power Query Table'!P:P,'Power Query Table'!O:O,'Upload tab'!K40) -> 0 | M40: =INDEX('Membership invoices'!$32:$32,MATCH('Upload tab'!K40,'Membership invoices'!$5:$5,0)) -> #N/A | N40: =L40=M40 -> #N/A
L41: =SUMIFS('Power Query Table'!P:P,'Power Query Table'!O:O,'Upload tab'!K41) -> 0 | M41: =INDEX('Membership invoices'!$180:$180,MATCH('Upload tab'!K41,'Membership invoices'!$5:$5,0)) -> #N/A | N41: =L41=M41 -> #N/A
L42: =SUMIFS('Power Query Table'!P:P,'Power Query Table'!O:O,'Upload tab'!K42) -> 0 | M42: =INDEX('Membership invoices'!$180:$180,MATCH('Upload tab'!K42,'Membership invoices'!$5:$5,0)) -> #N/A | N42: =L42=M42 -> #N/A
L43: =SUMIFS('Power Query Table'!P:P,'Power Query Table'!O:O,'Upload tab'!K43) -> 0 | M43: =INDEX('Membership invoices'!$180:$180,MATCH('Upload tab'!K43,'Membership invoices'!$5:$5,0)) -> #N/A | N43: =L43=M43 -> #N/A
L44: =SUMIFS('Power Query Table'!P:P,'Power Query Table'!O:O,'Upload tab'!K44) -> 0 | M44: =INDEX('Membership invoices'!$180:$180,MATCH('Upload tab'!K44,'Membership invoices'!$5:$5,0)) -> #N/A | N44: =L44=M44 -> #N/A
L45: =SUMIFS('Power Query Table'!P:P,'Power Query Table'!O:O,'Upload tab'!K45) -> 0 | M45: =INDEX('Membership invoices'!$192:$192,MATCH('Upload tab'!K45,'Membership invoices'!$5:$5,0)) -> #N/A | N45: =L45=M45 -> #N/A
L46: =SUMIFS('Power Query Table'!P:P,'Power Query Table'!O:O,'Upload tab'!K46) -> 0 | M46: =INDEX('Membership invoices'!$192:$192,MATCH('Upload tab'!K46,'Membership invoices'!$5:$5,0)) -> #N/A | N46: =L46=M46 -> #N/A
L47: =SUMIFS('Power Query Table'!P:P,'Power Query Table'!O:O,'Upload tab'!K47) -> 0 | M47: =INDEX('Membership invoices'!$192:$192,MATCH('Upload tab'!K47,'Membership invoices'!$5:$5,0)) -> #N/A | N47: =L47=M47 -> #N/A
L48: =SUMIFS('Power Query Table'!P:P,'Power Query Table'!O:O,'Upload tab'!K48) -> 0 | M48: =INDEX('Membership invoices'!$192:$192,MATCH('Upload tab'!K48,'Membership invoices'!$5:$5,0)) -> #N/A | N48: =L48=M48 -> #N/A
L49: =SUMIFS('Power Query Table'!P:P,'Power Query Table'!O:O,'Upload tab'!K49) -> 0 | M49: =INDEX('Membership invoices'!$192:$192,MATCH('Upload tab'!K49,'Membership invoices'!$5:$5,0)) -> #N/A | N49: =L49=M49 -> #N/A
L50: =SUMIFS('Power Query Table'!P:P,'Power Query Table'!O:O,'Upload tab'!K50) -> 0 | M50: =INDEX('Membership invoices'!$192:$192,MATCH('Upload tab'!K50,'Membership invoices'!$5:$5,0)) -> #N/A | N50: =L50=M50 -> #N/A
...

Sheet Data Details ->>

Sheet Sheet1
A1: L3917096 | B1: =_xlfn.XLOOKUP(A1,#REF!,#REF!,"",0,1) -> #REF! | D1: L3917096 | F1: Invoice #
A2: L3917104 | B2: =_xlfn.XLOOKUP(A2,#REF!,#REF!,"",0,1) -> #REF! | D2: L3917104 | F2: L3917096
A3: L3917111 | B3: =_xlfn.XLOOKUP(A3,#REF!,#REF!,"",0,1) -> #REF! | D3: L3917111 | F3: L3917104
A4: L3917336 | B4: =_xlfn.XLOOKUP(A4,#REF!,#REF!,"",0,1) -> #REF! | D4: L3917336 | F4: L3917111
A5: L3917283 | B5: =_xlfn.XLOOKUP(A5,#REF!,#REF!,"",0,1) -> #REF! | D5: L3917283 | F5: L3917336
A6: L3917544 | B6: =_xlfn.XLOOKUP(A6,#REF!,#REF!,"",0,1) -> #REF! | D6: L3917544 | F6: L3917283
A7: L3917618 | B7: =_xlfn.XLOOKUP(A7,#REF!,#REF!,"",0,1) -> #REF! | D7: L3917618 | F7: L3917544
A8: L3917619 | B8: =_xlfn.XLOOKUP(A8,#REF!,#REF!,"",0,1) -> #REF! | D8: L3917619 | F8: L3917618
A9: L3917786 | B9: =_xlfn.XLOOKUP(A9,#REF!,#REF!,"",0,1) -> #REF! | D9: L3917786 | F9: L3917619
A10: L3918046 | B10: =_xlfn.XLOOKUP(A10,#REF!,#REF!,"",0,1) -> #REF! | D10: L3918046 | F10: L3917786
A11: L3918086 | B11: =_xlfn.XLOOKUP(A11,#REF!,#REF!,"",0,1) -> #REF! | D11: L3918086 | F11: L3918046
A12: L3918256 | B12: =_xlfn.XLOOKUP(A12,#REF!,#REF!,"",0,1) -> #REF! | D12: L3918256 | F12: L3918086
... A179: L2404494 | B179: =_xlfn.XLOOKUP(A179,#REF!,#REF!,"",0,1) -> #REF! | D179: L2404494 | F179: L3924297
F180: L3924298
F181: L3924303
F182: L3924306
F183: L39N00306
F184: L2404162
F185: L2404214
F186: L2404208
F187: L2404270
F188: L2404254
F189: L2404425
F190: L2404424
F191: L2404489
... F193: L2404494

Sheet Power Query Table
A1: Invoice # | B1: Name | C1: Email | D1: Invoice From | E1: Invoice To | F1: Raised on | G1: Due on | H1: Paid On | I1: Total Tax | J1: Column2 | K1: Column3 | L1: Column1 | M1: Total | N1: Paid | O1: Attribute | P1: Value
A2: L3924638 | B2: JEB ENGINEERING SERVICES LLP | C2: nb729@jbs.cam.ac.uk | D2: 45839 | E2: 45870 | F2: 45866.692 | G2: 45873.692 | H2: 45860 | I2: 88 | J2: =Table1__4[[#This Row],[Value]]*0.2 -> 88 | K2: =Table1__4[[#This Row],[Total Tax]]-Table1__4[[#This Row],[Column2]] -> 0 | L2: =Table1__4[[#This Row],[Value]]*1.2 -> 528 | M2: 528 | N2: TRUE | O2: 4211-3011 - L39 Hot Desk Membership (2024) | P2: 440
I3: =SUM(Table1__4[Total Tax]) -> 88 | M3: =SUM(Table1__4[Total]) -> 528

Sheet Membership invoices

Sheet Mapping
A2: Mapping
A3: 4211-3011 | B3: c0000035 | C3: Lvl 39
A4: 4211-4011 | B4: c0000035 | C4: Lvl 39
A5: 4211-2011 | B5: c0000035 | C5: Lvl 39
A6: 5275-9500 | B6: c0000035 | C6: Lvl 39
A7: 4211-9031 | B7: c0000035 | C7: Lvl 39
A8: 2521-1112 | B8: c0000035 | C8: Lvl 39
A9: 4211-1011 | B9: c0000008 | C9: Lvl 24
A10: 2723-0621 | B10: c0000035 | C10: Lvl 39
A11: 4211201 - | B11: c0000035 | C11: Lvl 39
A12: 4211404 - | B12: c0000035 | C12: Lvl 39
A13: 4211118 - | B13: c0000035 | C13: Lvl 39
A14: 4211708 - | B14: c0000035 | C14: Lvl 39
... A24: 4211-7061 | B24: c0000035 | C24: Lvl 39
A25: 2521830 -
A26: 4211303 - | B26: c0000035 | C26: Lvl 39
A27: 2521830/L
A28: 4211409 - | B28: c0000035 | C28: Lvl 39
A29: 4211202 - | B29: c0000035 | C29: Lvl 39
A30: 4211801 - | B30: c0000035 | C30: Lvl 39

Sheet Recoverability
F1: KEY
F2: Code | G2: DEP | H2: RENT | I2: GEN | J2: CON | K2: DIR | L2: EW | M2: TS | N2: AE | O2: PART | P2: INS | Q2: RES | R2: SF | S2: SC | T2: RP | U2: UN | V2: EST | W2: DEPTDS
B3: Property Recoverability Aid as at 8 March 2025 | F3: Description | G3: Deposits | H3: Rent | I3: General | J3: Construction | K3: Direct Tenant Charges | L3: East Wintergarden | M3: Tenant Services | N3: Arts & Events | O3: Public Art | P3: Insurance | Q3: Reserve Fund | R3: Sinking Fund | S3: Service Charge | T3: Retail Promotions | U3: Unallocated Cash | V3: Estate | W3: Custodial Deposits
F4: Note: This report shows the recoverabilities set up for each property/entity.
B5: Property | C5: Prop Description | D5: Recovery
B6: c001 | C6: Canary Wharf Limited | D6: GEN^UN^CON
B7: c002 | C7: Canary Wharf Contractors Limited | D7: CON^GEN
B8: c003 | C8: Heron Quays Properties Limited | D8: GEN^UN^EW
B9: c004 | C9: Canary Wharf Investments Limited | D9: GEN^UN^RENT
B10: c005 | C10: Cabot Place Limited | D10: GEN^UN^RENT
B11: c006 | C11: Canary Wharf Management Limited | D11: GEN^UN^SC^TS^RP
B12: c007 | C12: South Quay Properties Limited | D12: GEN^UN
B13: c008 | C13: DORMANT - Seven Westferry Circus Limited | D13: GEN^UN
B14: c014 | C14: Canary Wharf Investments (Two) Limited | D14: GEN^UN
B15: c015 | C15: Canary Wharf Investments (Three) | D15: GEN^UN
B16: c016 | C16: DORMANT - First Tower T1 Limited | D16: GEN^UN
... B69: c091 | C69: Canary Wharf Group plc | D69: GEN^UN^RENT
B70: c0a2 | C70: CLOSED - Canary Wharf Finance Limited
B71: c0a4 | C71: CW Properties DS7B Limited | D71: GEN^UN
B72: c0a5 | C72: CW Leasing DS7B Limited | D72: GEN^UN^RENT^INS
B73: c0a7 | C73: CW Properties DS7F Limited | D73: GEN^UN
B74: c0a8 | C74: CW Leasing DS7F Limited | D74: GEN^UN^RENT^INS
B75: c0ac | C75: CLOSED - One Canada Square (Retail) Unit Trust | D75: GEN^UN
B76: c0af | C76: CLOSED - Canada Place (Retail) Unit Trust | D76: GEN^UN
B77: c0ai | C77: CLOSED - Cabot Place (Retail) Unit Trust | D77: GEN^UN
B78: c0al | C78: CLOSED - Canada Place Mall (Retail) Unit Trust | D78: GEN^UN
B79: c0ao | C79: CLOSED - Jubilee Place (Retail) Unit Trust | D79: GEN^UN
B80: c0ar | C80: 10 Cabot Square I Unit Trust | D80: GEN^UN
B81: c0au | C81: 10 Cabot Square II Unit Trust | D81: GEN^UN
B82: c0ax | C82: 20 Cabot Square I Unit Trust | D82: GEN^UN
... B85: c0ba | C85: 20 Cabot Square II Unit Trust | D85: GEN^UN
B86: c0bd | C86: CLOSED - Canary Wharf Finance III Limited
B87: c0bf | C87: 10 Cabot Square I Unit Trust LP Limited | D87: GEN^UN
B88: c0bg | C88: 10 Cabot Square I Unit Trust GP Limited | D88: GEN^UN
B89: c0bh | C89: 10 Cabot Square I Unit Trust SLP | D89: GEN^UN
B90: c0bj | C90: 10 Cabot Square II Unit Trust LP Limited | D90: GEN^UN
B91: c0bk | C91: 10 Cabot Square II Unit Trust GP Limited | D91: GEN^UN
B92: c0bl | C92: 10 Cabot Square II Unit Trust SLP | D92: GEN^UN
B93: c0bm | C93: 20 Cabot Square I Unit Trust LP Limited | D93: GEN^UN
B94: c0bn | C94: 20 Cabot Square I Unit Trust GP Limited | D94: GEN^UN
...

Sheet IC Codes
C3: IC Segment Tree as at 14 Mar 2025 | H3: Note: The codes below require the IC segment to be populated with the entity/property the intercompany is with
C4: GL Acc | D4: Code | E4: Description | H4: GL Acc Paired | I4: GL Acc Description 2
C5: 10516011 | D5: 1051-6011 | E5: Internal Investments - historic cost | F5: IC Required | J5: IC Required
C6: 10516019 | D6: 1051-6019 | E6: Internal Investments - Provision | F6: IC Required | J6: IC Required
C7: 10516021 | D7: 1051-6021 | E7: Internal Investments - profit accrual | F7: IC Required | J7: IC Required
C8: 10516031 | D8: 1051-6031 | E8: Internal Investments - parternship loans | F8: IC Required | J8: IC Required
C9: 10516041 | D9: 1051-6041 | E9: Internal Investments - share of revaluation | F9: IC Required | J9: IC Required
C10: 11080113 | D10: 1108-0113 | E10: Construction: construction management (CM) fees | F10: IC Required | J10: IC Required
C11: 11080114 | D11: 1108-0114 | E11: Construction: development management (DM) fees | F11: IC Required | J11: IC Required
C12: 11800033 | D12: 1180-0033 | E12: IC Non-Certified Accruals flow (with jobs) - IN | F12: IC Required | H12: 1180-0034 | I12: IC Non-Certified Accruals flow (with jobs) - OUT | J12: IC Required
C13: 11800034 | D13: 1180-0034 | E13: IC Non-Certified Accruals flow (with jobs) - OUT | F13: IC Required | H13: 1180-0033 | I13: IC Non-Certified Accruals flow (with jobs) - IN | J13: IC Required
C14: 11800040 | D14: 1180-0040 | E14: IC WIP Transfers (with jobs) - IN | F14: IC Required | H14: 1180-0041 | I14: I/C WIP Transfers | J14: IC Required
C15: 11800041 | D15: 1180-0041 | E15: I/C WIP Transfers | F15: IC Required | H15: 1180-0040 | I15: IC WIP Transfers (with jobs) - IN | J15: IC Required
C16: 11800042 | D16: 1180-0042 | E16: I/C WIP Transfers (no jobs) | F16: IC Required | J16: IC Required
C17: 11800043 | D17: 1180-0043 | E17: I/C WIP Billing (with jobs) | F17: IC Required | H17: 1180-0044 | I17: IC WIP Billing (with jobs) - OUT | J17: IC Required
C18: 11800044 | D18: 1180-0044 | E18: IC WIP Billing (with jobs) - OUT | F18: IC Required | H18: 1180-0043 | I18: I/C WIP Billing (with jobs) | J18: IC Required
C19: 13151000 | D19: 1315-1000 | E19: Interco-setoffs | F19: IC Required | J19: IC Required
C20: 13151001 | D20: 1315-1001 | E20: Interco - Current (receivable) | F20: IC Required | H20: 1315-1001 | I20: Interco - Current (receivable) | J20: IC Required
C21: 13151002 | D21: 1315-1002 | E21: Interco - Loan Interest (receivable) | F21: IC Required | H21: 2415-1002 | I21: Interco - Loan Interest (payable) | J21: IC Required
C22: 13151003 | D22: 1315-1003 | E22: Interco - Loans (receivable) | F22: IC Required | H22: 2415-1003 | I22: Interco - Loans (payable) | J22: IC Required
C23: 13151006 | D23: 1315-1006 | E23: Interco - Loans Swap Adj. (receivable) | F23: IC Required | H23: 2415-1006 | I23: Interco - Loans Swap Adj. (payable) | J23: IC Required
C24: 13151007 | D24: 1315-1007 | E24: Interco - Loan Fees (receivable) | F24: IC Required | H24: 2415-1007 | I24: Interco - Loan Fees (payable) | J24: IC Required
C25: 13151009 | D25: 1315-1009 | E25: Provision against IC debtor | F25: IC Required | J25: IC Required
C26: 13151011 | D26: 1315-1011 | E26: Interco - Finance Rents Payments (receivable) | F26: IC Required | H26: 2415-1011 | I26: Interco - Finance Rents Payments (payable) | J26: IC Required
C27: 13151021 | D27: 1315-1021 | E27: Interco - Finance Lease SSAP21 (receivable) | F27: IC Required | H27: 2415-1021 | I27: Interco - Finance Lease SSAP21 (payable) | J27: IC Required
C28: 13151031 | D28: 1315-1031 | E28: Interco - Finance Lease Creditor (receivable) | F28: IC Required | H28: 2415-1031 | I28: Interco - Finance Lease Creditor (payable) | J28: IC Required
C29: 13151041 | D29: 1315-1041 | E29: Interco – Discount on acquisition (receivable) | F29: IC Required | H29: 2415-1041 | I29: Interco – Discount on acquisition (payable) | J29: IC Required
C30: 13152001 | D30: 1315-2001 | E30: Interco - IC Incentives (receivable) | F30: IC Required | H30: 2415-2001 | I30: Interco - IC Incentives (payable) | J30: IC Required
C31: 13153001 | D31: 1315-3001 | E31: Interco - Voids accruals | F31: IC Required | H31: 1315-3001 | I31: Interco - Voids accruals | J31: IC Required
C32: 13154001 | D32: 1315-4001 | E32: Interco - Wood Wharf contribution agreement | F32: IC Required | J32: IC Required
C33: 13161601 | D33: 1316-1601 | E33: Interco - Other Loans (receivable) | F33: IC Required | H33: 2416-1601 | I33: Interco - Other Loans (payable) | J33: IC Required
C34: 13161611 | D34: 1316-1611 | E34: Interco - Other Loan Interest (receivable) | F34: IC Required | H34: 2416-1611 | I34: Interco Loan Interest (payable) | J34: IC Required
C35: 13161621 | D35: 1316-1621 | E35: Interco - Other Loan Fees (receivable) | F35: IC Required | H35: 2416-1621 | I35: Interco - Other Loan Fees (payable) | J35: IC Required
C36: 13161631 | D36: 1316-1631 | E36: Interco - Other Loan Fair Value Adjustment (receivable) | F36: IC Required | H36: 2416-1631 | I36: Interco - Other Loan Fair Value Adjustment (payable) | J36: IC Required
C37: 13161641 | D37: 1316-1641 | E37: Interco - Other Loan Provision (receivable) | F37: IC Required | H37: 2416-1641 | I37: Interco - Other Loan Provision (payable) | J37: IC Required
C38: 13161661 | D38: 1316-1661 | E38: Interco - Eurobonds (receivable) | F38: IC Required | H38: 2416-1661 | I38: Interco - Eurobonds (payable) | J38: IC Required
C39: 13161662 | D39: 1316-1662 | E39: IC Loans (receivable) – Spens | F39: IC Required | H39: 2416-1662 | I39: IC Loans (payable) – Spens | J39: IC Required
C40: 15059001 | D40: 1505-9001 | E40: IC PP - Office and Retail Rents | F40: IC Required | H40: 2723-9001 | I40: Deferred Intercompany - Office and Retail Rents | J40: IC Required
C41: 15059011 | D41: 1505-9011 | E41: IC PP - Ground Rents | F41: IC Required | H41: 2723-9011 | I41: Deferred Intercompany - Ground Rents | J41: IC Required
C42: 15059021 | D42: 1505-9021 | E42: IC PP - UITF28 REnt Adjustments | F42: IC Required | H42: 2723-9021 | I42: Deferred Intercompany - UITF28 Rent Adjustments | J42: IC Required
...

Sheet Budget
B2: Budget Segment Accounts as at 8 March 2025
B4: Account | C4: Acct Description | D4: Expense Type / Budget Segment | E4: Validation Rules | F4: Budget Tree
B5: 1021-2461 | C5: Plant and Machinery | D5: IT^Information Technology^Unexpected Costs^IC Ad Hoc | E5: 1021-2461 | F5: 1021-2461
B6: 1021-2481 | C6: Computer Hardware | D6: IT^Information Technology^Treasury^Unexpected Costs^IC Ad Hoc | E6: 1021-2481 | F6: 1021-2481
B7: 1021-2488 | C7: Disaster Recovery Costs | D7: IT^Unexpected Costs^IC Ad Hoc | E7: 1021-2488 | F7: 1021-2488
B8: 1021-2501 | C8: Computer Software | D8: IT^Treasury^Unexpected Costs^IC Ad Hoc | E8: 1021-2501 | F8: 1021-2501
B9: 1031-2421 | C9: Fixtures and Equipment | D9: Facilities^Corp Bldg Serv^VRML O/H^Lvl39^Level39^Unexpected Costs^IC Ad Hoc | E9: 1031-2421 | F9: 1031-2421
B10: 1031-2501 | C10: F&F cost oracle legacy | D10: Corp Bldg Serv^Unexpected Costs^IC Ad Hoc | E10: 1031-2501 | F10: 1031-2501
B11: 1108-1320 | C11: Tenant Inducement Costs | D11: Office Leasing^Leasing Office^Leasing Retail^Unexpected Costs^IC Ad Hoc^Retail Projects | E11: 1108-1320 | F11: 1108-1320
B12: 1108-5012 | C12: Tenant Construction Retail (without job) | D12: CapCon^CapCon Retail^Retail Works^Unexpected Costs^IC Ad Hoc^Retail Projects | E12: 1108-5012 | F12: 1108-5012
B13: 1108-5013 | C13: Tenant Construction Office (with job) | D13: Leasing Office^Unexpected Costs^IC Ad Hoc | E13: 1108-5013 | F13: 1108-5013
B14: 1404-9311 | C14: FFL - Recharges / Claims | D14: ELBP/BL/SLPN^IC Ad Hoc^Unexpected Costs | E14: 1404-9311 | F14: 1404-9311
B15: 1404-9321 | C15: FFL - Marketing and Publicity | D15: ELBP/BL/SLPN^IC Ad Hoc^Unexpected Costs | E15: 1404-9321 | F15: 1404-9321
... B79: 5781-3111 | C79: IPTV costs | D79: Telecoms^Unexpected Costs^IC Ad Hoc^Information Technology | E79: 5781-3111 | F79: 5781-3111
B80: 6154-5411 | C80: INACITVE: Planning General | D80: Unexpected Costs^IC Ad Hoc^Leasing Office^Feas/Model/Plan | F80: 6154-5411
B81: 6154-6811 | C81: Memberships | D81: CWRML O/H^Unexpected Costs^IC Ad Hoc^Corp Affairs^Mktg Vertus^Leasing Retail^Customer Experience^VRML O/H^Sustainability^Vertus Mgmt | E81: 6154-6811 | F81: 6154-6811
B82: 6162-1000 | C82: Total Payroll Costs - Overheads | D82: Unexpected Costs^Payroll^IC Ad Hoc | E82: 6162-1000 | F82: 6162-1000
B83: 6162-1411 | C83: BUPA/Life Assurance/Disability | D83: CWRML O/H^Payroll^Mktg Vertus^VRML O/H^IC Ad Hoc | E83: 6162-1411 | F83: 6162-1411
B84: 6162-1501 | C84: Redundancy | D84: Unexpected Costs^Payroll^IC Ad Hoc | F84: 6162-1501
B85: 6162-2911 | C85: LTIP Share Option Scheme | D85: Unexpected Costs^Payroll^IC Ad Hoc | E85: 6162-2911 | F85: 6162-2911
B86: 6162-5821 | C86: Employee professional subscriptions | D86: CWRML O/H^Unexpected Costs^CoSec^Leasing Office^Legal^Payroll^Ppl and Dev^Press Office^Donations^Leasing Resi^Mktg Office^Mktg Resi^Mktg Retail^Mktg Vertus^Leasing Retail^Corp Bldg Serv^Tax^VRML O/H^IT^Insurance^Sustainability^Accounts^IC Ad Hoc | E86: 6162-5821 | F86: 6162-5821
B87: 6162-5911 | C87: Hiring and Recruitment | D87: Unexpected Costs^Payroll^Ppl and Dev^VRML O/H^Vertus Mgmt^IC Ad Hoc | E87: 6162-5911 | F87: 6162-5911
B88: 6162-6111 | C88: Payroll - QIA Non Exec Fees | D88: Unexpected Costs^Payroll^Reward and Benefits^IC Ad Hoc | E88: 6162-6111 | F88: 6162-6111
B89: 6163-0311 | C89: Audit Fees - Statutory | D89: Unexpected Costs^Accounts^IC Ad Hoc | E89: 6163-0311 | F89: 6163-0311
B90: 6163-0371 | C90: External valuation fees | D90: Valuations^Unexpected Costs^Prop Valuations^Accounts^IC Ad Hoc | E90: 6163-0371 | F90: 6163-0371
B91: 6163-0411 | C91: Taxation Fees | D91: Tax^IC Ad Hoc | E91: 6163-0411 | F91: 6163-0411
B92: 6163-0606 | C92: Legal - Dev Misc | D92: Legal^IC Ad Hoc | E92: 6163-0606 | F92: 6163-0606
B93: 6163-0811 | C93: Bank Charges (Admin expenses) | D93: CWRML O/H^Payroll^Mktg Vertus^VRML O/H^IC Ad Hoc | E93: 6163-0811 | F93: 6163-0811
B94: 6163-5011 | C94: Professional Fees | D94: Rates^Legal^Payroll^Ppl and Dev^Mktg Vertus^VRML O/H^Accounts^IC Ad Hoc | E94: 6163-5011 | F94: 6163-5011
B95: 6164-0411 | C95: Subscriptions/Manuals | D95: CoSec^Legal^Ppl and Dev^Tax^IT^IC Ad Hoc | E95: 6164-0411 | F95: 6164-0411
B96: 6164-0711 | C96: Software Maintenance | D96: Unexpected Costs^VRML O/H^IT^Vertus Mgmt^IC Ad Hoc | E96: 6164-0711 | F96: 6164-0711
... B122: 9110-0111 | C122: UK Corporation Tax | D122: HMRC^Taxation^Unexpected Costs^IC Ad Hoc | E122: 9110-0111 | F122: 9110-0111

Sheet VAT
A3: Tax Rate Lookup | B3: Vat Rates | C3: AP Tax Types | D3: AR Tax Tran Types | E3: Tax Rates Codes
A4: ukstd20 | B4: 0.2 | C4: purch | D4: sales | E4: ukstd20
A5: ukred5 | B5: 0.05 | C5: purch | D5: sales | E5: ukred5
A6: ukzero | B6: 0 | C6: purch | D6: sales | E6: ukzero
A7: exempt | B7: Exempt | C7: expurch | D7: exsales
A8: outside | B8: Outside | C8: oospurch | D8: oossales

Sheet CoA
B4: Chart of Accounts as at 14 Mar 2025
B6: Account | C6: Account Name | D6: Normal | E6: Acct | F6: Rpt | H6: Line | I6: Offset | J6: Hold-For | K6: Accrual | L6: Total | M6: Flags
D7: Balance | E7: Type | F7: Type | G7: Margin | H7: Adv. | I7: Account | J7: Account | K7: Account | L7: Account
B8: 1000-0000 | C8: BALANCE SHEET | D8: Debit | E8: Head | F8: Bal | G8: 0 | H8: 0
B9: 1001-0000 | C9: FIXED ASSET | D9: Debit | E9: Head | F9: Bal | G9: 0 | H9: 0 | L9: 1099-9999
B10: 1002-0000 | C10: Tangible Fixed Asset | D10: Debit | E10: Head | F10: Bal | G10: 0 | H10: 0 | L10: 1049-9999
B11: 1010-0000 | C11: Land and Buildings | D11: Debit | E11: Head | F11: Bal | G11: 0 | H11: 0 | L11: 1019-9999
B12: 1011-2301 | C12: Interest in Freehold Land | D12: Debit | E12: Reg | F12: Bal | G12: 3 | H12: 0 | L12: 1019-9999
B13: 1011-2302 | C13: Disposal of interest in Freehold Land | D13: Debit | E13: Reg | F13: Bal | G13: 3 | H13: 0 | L13: 1019-9999
B14: 1011-2303 | C14: Provision against Freehold Land | D14: Debit | E14: Reg | F14: Bal | G14: 3 | H14: 0 | L14: 1019-9999
B15: 1011-2304 | C15: Properties Under Construction | D15: Debit | E15: Reg | F15: Bal | G15: 3 | H15: 1 | L15: 1019-9999
B16: 1011-2305 | C16: Development Properties | D16: Debit | E16: Reg | F16: Bal | G16: 3 | H16: 1 | L16: 1019-9999
B17: 1011-2310 | C17: Revaluation of Freehold Land | D17: Debit | E17: Reg | F17: Bal | G17: 3 | H17: 0 | L17: 1019-9999
B18: 1011-2311 | C18: Interest in Property | D18: Debit | E18: Reg | F18: Bal | G18: 3 | H18: 0 | L18: 1019-9999
B19: 1011-2312 | C19: Revaluation of Leasehold Property | D19: Debit | E19: Reg | F19: Bal | G19: 3 | H19: 0 | L19: 1019-9999
B20: 1011-2313 | C20: Disposal of interest in investment property | D20: Debit | E20: Reg | F20: Bal | G20: 3 | H20: 0 | L20: 1019-9999
... B116: 1108-0000 | C116: WIP | D116: Debit | E116: Head | F116: Bal | G116: 0 | H116: 0 | L116: 1199-9999
B117: 1108-0015 | C117: WIP Markup (with job) | D117: Debit | E117: Reg | F117: Bal | G117: 3 | H117: 1 | L117: 1199-9999 | M117: WIP
B118: 1108-0016 | C118: WIP Markup (no job) | D118: Debit | E118: Reg | F118: Bal | G118: 3 | H118: 1 | L118: 1199-9999
B119: 1108-0044 | C119: INACTIVE: IC WIP Billing (with jobs) - OUT | D119: Debit | E119: Reg | F119: Bal | G119: 3 | H119: 1 | L119: 1199-9999 | M119: Exclude, WIP
B120: 1108-0111 | C120: Construction: Base Building | D120: Debit | E120: Reg | F120: Bal | G120: 3 | H120: 1 | L120: 1199-9999 | M120: WIP
B121: 1108-0112 | C121: Construction retention | D121: Debit | E121: Reg | F121: Bal | G121: 0 | H121: 1 | L121: 1199-9999 | M121: WIP
B122: 1108-0113 | C122: Construction: construction management (CM) fees | D122: Debit | E122: Reg | F122: Bal | G122: 3 | H122: 1 | L122: 1199-9999 | M122: WIP
B123: 1108-0114 | C123: Construction: development management (DM) fees | D123: Debit | E123: Reg | F123: Bal | G123: 3 | H123: 1 | L123: 1199-9999 | M123: WIP
B124: 1108-0211 | C124: Construction Under Brackendown Contract | D124: Debit | E124: Reg | F124: Bal | G124: 3 | H124: 0 | L124: 1199-9999
B125: 1108-0411 | C125: Inter-Company Property Disposals | D125: Debit | E125: Reg | F125: Bal | G125: 3 | H125: 1 | L125: 1199-9999
B126: 1108-0511 | C126: External Property Disposals | D126: Debit | E126: Reg | F126: Bal | G126: 3 | H126: 0 | L126: 1199-9999
B127: 1108-0521 | C127: External Property Disposals - SSAP9 | D127: Debit | E127: Reg | F127: Bal | G127: 3 | H127: 0 | L127: 1199-9999
B128: 1108-0611 | C128: IC WIP purchases | D128: Debit | E128: Reg | F128: Bal | G128: 3 | H128: 1 | L128: 1199-9999
B129: 1108-0811 | C129: WIP transfers to property (Buildings) | D129: Debit | E129: Reg | F129: Bal | G129: 3 | H129: 0 | L129: 1199-9999
B130: 1108-0821 | C130: WIP - Year end transfers to fixed assets | D130: Debit | E130: Reg | F130: Bal | G130: 3 | H130: 0 | L130: 1199-9999
B131: 1108-0911 | C131: External Property Purchases | D131: Debit | E131: Reg | F131: Bal | G131: 3 | H131: 0 | L131: 1199-9999
B132: 1108-1011 | C132: External land purchases | D132: Debit | E132: Reg | F132: Bal | G132: 3 | H132: 0 | L132: 1199-9999
B133: 1108-1021 | C133: British Waterways Density payment | D133: Debit | E133: Reg | F133: Bal | G133: 3 | H133: 0 | L133: 1199-9999
B134: 1108-1031 | C134: Stamp Duty Land Tax (SDLT) | D134: Debit | E134: Reg | F134: Bal | G134: 3 | H134: 0 | L134: 1199-9999
B135: 1108-1041 | C135: British Waterways Density agreement fees | D135: Debit | E135: Reg | F135: Bal | G135: 3 | H135: 0 | L135: 1199-9999
B136: 1108-1051 | C136: ECC costs to infrastructure | D136: Debit | E136: Reg | F136: Bal | G136: 3 | H136: 0 | L136: 1199-9999
B137: 1108-1061 | C137: S106 agreement | D137: Debit | E137: Reg | F137: Bal | G137: 3 | H137: 1 | L137: 1199-9999 | M137: WIP
B138: 1108-1071 | C138: SSAP 9 Legal Fees | D138: Debit | E138: Reg | F138: Bal | G138: 3 | H138: 0 | L138: 1199-9999
B139: 1108-1081 | C139: Acquisition legal fees | D139: Debit | E139: Reg | F139: Bal | G139: 3 | H139: 0 | L139: 1199-9999
...

Sheet Company Info
B3: Company Information as at 8 March 2025
B5: Oracle Code | C5: IM Entity | D5: Owner Code | E5: Owner Name | F5: Tax Authority | G5: Tax Point | H5: Currency | I5: Rate Provider | J5: Sales Type | K5: Purchase Type | L5: Registration Number | M5: TAX Last Reported on | N5: TAX Reporting Frequency | O5: Fiscal Entity Code | P5: Fiscal Entity | Q5: Commerce Reg Number | R5: City Of Registration
B6: =RIGHT($C6,2) -> 01 | C6: ="c0"&RIGHT($D6,2) -> c001 | D6: o001 | E6: Canary Wharf Limited | F6: uk | G6: Invoice | H6: gbp | I6: blo(spot) | J6: sales | K6: purch | L6: 512639654 | M6: 2/1/2025 | N6: Monthly | O6: vgrp001 | P6: VAT Group - Canary Wharf Limited | Q6: 01971312 | R6: UK
B7: =RIGHT($C7,2) -> 02 | C7: ="c0"&RIGHT($D7,2) -> c002 | D7: o002 | E7: Canary Wharf Contractors Limited | F7: uk | G7: Invoice | H7: gbp | I7: blo(spot) | J7: sales | K7: purch | L7: 507034774 | M7: 2/1/2025 | N7: Monthly | Q7: 02352250 | R7: UK
B8: =RIGHT($C8,2) -> 03 | C8: ="c0"&RIGHT($D8,2) -> c003 | D8: o003 | E8: Heron Quays Properties Limited | F8: uk | G8: Invoice | H8: gbp | I8: blo(spot) | J8: sales | K8: purch | L8: 512639654 | M8: 2/1/2025 | N8: Monthly | O8: vgrp001 | P8: VAT Group - Canary Wharf Limited | Q8: 02276627 | R8: UK
B9: =RIGHT($C9,2) -> 04 | C9: ="c0"&RIGHT($D9,2) -> c004 | D9: o004 | E9: Canary Wharf Investments Limited | F9: uk | G9: Invoice | H9: gbp | I9: blo(spot) | J9: sales | K9: purch | L9: 512639654 | M9: 2/1/2025 | N9: Monthly | O9: vgrp001 | P9: VAT Group - Canary Wharf Limited | Q9: 02127410 | R9: UK
B10: =RIGHT($C10,2) -> 05 | C10: ="c0"&RIGHT($D10,2) -> c005 | D10: o005 | E10: Cabot Place Limited | F10: uk | G10: Invoice | H10: gbp | I10: blo(spot) | J10: sales | K10: purch | L10: 549233923 | M10: 1/1/2025 | N10: Quarterly | Q10: 02548110 | R10: UK
B11: =RIGHT($C11,2) -> 06 | C11: ="c0"&RIGHT($D11,2) -> c006 | D11: o006 | E11: Canary Wharf Management Limited | F11: uk | G11: Invoice | H11: gbp | I11: blo(spot) | J11: sales | K11: purch | L11: 512639654 | M11: 2/1/2025 | N11: Monthly | O11: vgrp001 | P11: VAT Group - Canary Wharf Limited | Q11: 02067510 | R11: UK
B12: =RIGHT($C12,2) -> 07 | C12: ="c0"&RIGHT($D12,2) -> c007 | D12: o007 | E12: South Quay Properties Limited | F12: uk | G12: Invoice | H12: gbp | I12: blo(spot) | J12: sales | K12: purch | L12: 161772993 | M12: 2/1/2025 | N12: Quarterly | Q12: 02830131 | R12: UK
B13: =RIGHT($C13,2) -> 08 | C13: ="c0"&RIGHT($D13,2) -> c008 | D13: o008 | E13: Seven Westferry Circus Limited | F13: uk | G13: n/a | H13: gbp | I13: blo(spot) | M13: 2/1/2025 | N13: Monthly | Q13: 02732071 | R13: UK
B14: =RIGHT($C14,2) -> 14 | C14: ="c0"&RIGHT($D14,2) -> c014 | D14: o014 | E14: Canary Wharf Investments (Two) Limited | F14: uk | G14: n/a | H14: gbp | I14: blo(spot) | M14: 2/1/2025 | N14: Monthly | Q14: 02863616 | R14: UK
B15: =RIGHT($C15,2) -> 15 | C15: ="c0"&RIGHT($D15,2) -> c015 | D15: o015 | E15: Canary Wharf Investments (Three) | F15: uk | G15: n/a | H15: gbp | I15: blo(spot) | M15: 2/1/2025 | N15: Monthly | Q15: 02455786 | R15: UK
B16: =RIGHT($C16,2) -> 16 | C16: ="c0"&RIGHT($D16,2) -> c016 | D16: o016 | E16: First Tower T1 Limited | F16: uk | G16: n/a | H16: gbp | I16: blo(spot) | M16: 2/1/2025 | N16: Monthly | Q16: 02550906 | R16: UK
B17: =RIGHT($C17,2) -> 17 | C17: ="c0"&RIGHT($D17,2) -> c017 | D17: o017 | E17: First Tower T2 Limited | F17: uk | G17: n/a | H17: gbp | I17: blo(spot) | M17: 2/1/2025 | N17: Monthly | Q17: 02558070 | R17: UK
B18: =RIGHT($C18,2) -> 18 | C18: ="c0"&RIGHT($D18,2) -> c018 | D18: o018 | E18: First Tower GP(1) Limited | F18: uk | G18: n/a | H18: gbp | I18: blo(spot) | M18: 2/1/2025 | N18: Monthly | Q18: SC132920 | R18: SCOTTISH
B19: =RIGHT($C19,2) -> 19 | C19: ="c0"&RIGHT($D19,2) -> c019 | D19: o019 | E19: First Tower GP(2) Limited | F19: uk | G19: n/a | H19: gbp | I19: blo(spot) | M19: 2/1/2025 | N19: Monthly | Q19: SC132921 | R19: SCOTTISH
B20: =RIGHT($C20,2) -> 1a | C20: ="c0"&RIGHT($D20,2) -> c01a | D20: o01a | E20: SBP1 Sarl | F20: uk | G20: Invoice | H20: gbp | I20: blo(spot) | J20: sales | K20: purch | L20: 194324890 | M20: 12/1/2024 | N20: Quarterly
B21: =RIGHT($C21,2) -> 1b | C21: ="c0"&RIGHT($D21,2) -> c01b | D21: o01b | E21: Braeburn Estates (B4A) Limited Partnership Propman Co | F21: uk | G21: Invoice | H21: gbp | I21: blo(spot) | J21: sales | K21: purch | L21: 188636260 | M21: 12/1/2024 | N21: Quarterly | O21: vgrp0jg | P21: VAT Group - Braeburn Estates B4A (GP) Limited
B22: =RIGHT($C22,2) -> 1c | C22: ="c0"&RIGHT($D22,2) -> c01c | D22: o01c | E22: Braeburn Estates (B4B) Limited Partnership Propman Co | F22: uk | G22: Invoice | H22: gbp | I22: blo(spot) | J22: sales | K22: purch | L22: 188636554 | M22: 12/1/2024 | N22: Quarterly | O22: vgrp0jm | P22: VAT Group - Braeburn Estates B4B (GP) Limited
B23: =RIGHT($C23,2) -> 1d | C23: ="c0"&RIGHT($D23,2) -> c01d | D23: o01d | E23: Braeburn Estates (B5) Limited Partnership Propman Co | F23: uk | G23: Invoice | H23: gbp | I23: blo(spot) | J23: sales | K23: purch | L23: 188637649 | M23: 2/1/2025 | N23: Monthly | O23: vgrp0js | P23: VAT Group - Braeburn Estates B5 (GP) Limited
B24: =RIGHT($C24,2) -> 1e | C24: ="c0"&RIGHT($D24,2) -> c01e | D24: o01e | E24: Braeburn Estates (B6/7) Limited Partnership Propman Co | F24: uk | G24: Invoice | H24: gbp | I24: blo(spot) | J24: sales | K24: purch | L24: 188641271 | M24: 12/1/2024 | N24: Quarterly | O24: vgrp0jx | P24: VAT Group - Braeburn Estates B6/7 (GP) Limited
B25: =RIGHT($C25,2) -> 1f | C25: ="c0"&RIGHT($D25,2) -> c01f | D25: o01f | E25: Braeburn Estates Management Company Limited Propman Co | F25: uk | G25: Invoice | H25: gbp | I25: blo(spot) | J25: sales | K25: purch | L25: 210439253 | M25: 12/1/2024 | N25: Quarterly | O25: vgrp0ja | P25: VAT Group - Braeburn Estates Management Company Limited
B26: =RIGHT($C26,2) -> 1g | C26: ="c0"&RIGHT($D26,2) -> c01g | D26: o01g | E26: Braeburn Estates Retail Limited Propman Co | F26: uk | G26: Invoice | H26: gbp | I26: blo(spot) | J26: sales | K26: purch | L26: 210278054 | M26: 12/1/2024 | N26: Quarterly | O26: vgrp0kc | P26: VAT Group - Braeburn Estates Retail Limited
B27: =RIGHT($C27,2) -> 1h | C27: ="c0"&RIGHT($D27,2) -> c01h | D27: o01h | E27: SBP2 Sarl | F27: uk | G27: Invoice | H27: gbp | I27: blo(spot) | J27: sales | K27: purch | L27: 194324009 | M27: 12/1/2024 | N27: Quarterly
B28: =RIGHT($C28,2) -> 1k | C28: ="c0"&RIGHT($D28,2) -> c01k | D28: o01k | E28: Vertus 10 George Street Limited Propman Co | F28: uk | G28: Invoice | H28: gbp | I28: blo(spot) | J28: sales | K28: purch | L28: 343829287 | M28: 12/1/2024 | N28: Quarterly | O28: vgrp0rc | P28: VAT Group - Vertus 10 George Street Limited
B29: =RIGHT($C29,2) -> 1l | C29: ="c0"&RIGHT($D29,2) -> c01l | D29: o01l | E29: Vertus 8 Water Street Limited Propman Co | F29: uk | G29: Invoice | H29: gbp | I29: blo(spot) | J29: sales | K29: purch | L29: 346742875 | M29: 12/1/2024 | N29: Quarterly | O29: vgrp0rb | P29: VAT Group - Vertus 8 Water Street Limited
B30: =RIGHT($C30,2) -> 1m | C30: ="c0"&RIGHT($D30,2) -> c01m | D30: o01m | E30: Vertus Newfoundland Place Limited Propman Co | F30: uk | G30: Invoice | H30: gbp | I30: blo(spot) | J30: sales | K30: purch | L30: 387523660 | M30: 12/1/2024 | N30: Quarterly | O30: vgrp0vm | P30: VAT Group - Vertus Residential Management Limited
B31: =RIGHT($C31,2) -> 1n | C31: ="c0"&RIGHT($D31,2) -> c01n | D31: o01n | E31: Wood Wharf Estate Management Limited Propman Co | F31: uk | G31: Invoice | H31: gbp | I31: blo(spot) | J31: sales | K31: purch | L31: 208904508 | M31: 12/1/2024 | N31: Quarterly
B32: =RIGHT($C32,2) -> 1p | C32: ="c0"&RIGHT($D32,2) -> c01p | D32: o01p | E32: Canary Wharf Residential Management Limited Propman Co | F32: uk | G32: n/a | H32: gbp | I32: blo(spot) | M32: 2/1/2025 | N32: Monthly
B33: =RIGHT($C33,2) -> 1r | C33: ="c0"&RIGHT($D33,2) -> c01r | D33: o01r | E33: CW One Park Drive Limited Propman Co | F33: uk | G33: Invoice | H33: gbp | I33: blo(spot) | J33: sales | K33: purch | L33: 384584749 | M33: 12/1/2024 | N33: Quarterly | O33: vgrp0rg | P33: VAT Group - CW Wood Wharf Residential StaffCo Ltd
B34: =RIGHT($C34,2) -> 1s | C34: ="c0"&RIGHT($D34,2) -> c01s | D34: o01s | E34: CW 10 Park Drive Limited Propman Co | F34: uk | G34: Invoice | H34: gbp | I34: blo(spot) | J34: sales | K34: purch | L34: 384584749 | M34: 12/1/2024 | N34: Quarterly | O34: vgrp0rg | P34: VAT Group - CW Wood Wharf Residential StaffCo Ltd
B35: =RIGHT($C35,2) -> 32 | C35: ="c0"&RIGHT($D35,2) -> c032 | D35: o032 | E35: First Tower Limited Partnership | F35: uk | G35: n/a | H35: gbp | I35: blo(spot) | M35: 2/1/2025 | N35: Monthly | Q35: LP004097 | R35: UK
B36: =RIGHT($C36,2) -> 34 | C36: ="c0"&RIGHT($D36,2) -> c034 | D36: o034 | E36: Canary Wharf Investments (Four) Limited | F36: uk | G36: n/a | H36: gbp | I36: blo(spot) | M36: 2/1/2025 | N36: Monthly | Q36: 02388957 | R36: UK
B37: =RIGHT($C37,2) -> 38 | C37: ="c0"&RIGHT($D37,2) -> c038 | D37: o038 | E37: CWE SPV SUPER HCo Limited | F37: uk | G37: n/a | H37: gbp | I37: blo(spot) | M37: 2/1/2025 | N37: Monthly | Q37: 03123346 | R37: UK
B38: =RIGHT($C38,2) -> 39 | C38: ="c0"&RIGHT($D38,2) -> c039 | D38: o039 | E38: CWE SPV HCo Limited | F38: uk | G38: n/a | H38: gbp | I38: blo(spot) | M38: 2/1/2025 | N38: Monthly | Q38: 03123311 | R38: UK
B39: =RIGHT($C39,2) -> 42 | C39: ="c0"&RIGHT($D39,2) -> c042 | D39: o042 | E39: CWE SPVc Limited | F39: uk | G39: n/a | H39: gbp | I39: blo(spot) | M39: 2/1/2025 | N39: Monthly | Q39: 03123343 | R39: UK
B40: =RIGHT($C40,2) -> 45 | C40: ="c0"&RIGHT($D40,2) -> c045 | D40: o045 | E40: CWE SPVf Limited | F40: uk | G40: n/a | H40: gbp | I40: blo(spot) | M40: 2/1/2025 | N40: Monthly | Q40: 03123299 | R40: UK
B41: =RIGHT($C41,2) -> 46 | C41: ="c0"&RIGHT($D41,2) -> c046 | D41: o046 | E41: CWE SPVg Limited | F41: uk | G41: n/a | H41: gbp | I41: blo(spot) | M41: 2/1/2025 | N41: Monthly | Q41: 03123286 | R41: UK
B42: =RIGHT($C42,2) -> 48 | C42: ="c0"&RIGHT($D42,2) -> c048 | D42: o048 | E42: CWC SPV HCo Limited | F42: uk | G42: n/a | H42: gbp | I42: blo(spot) | M42: 2/1/2025 | N42: Monthly | Q42: 03123064 | R42: UK
B43: =RIGHT($C43,2) -> 50 | C43: ="c0"&RIGHT($D43,2) -> c050 | D43: o050 | E43: CWC SPVa Limited | F43: uk | G43: Invoice | H43: gbp | I43: blo(spot) | J43: sales | K43: purch | L43: 751849895 | M43: 2/1/2025 | N43: Quarterly | Q43: 03123292 | R43: UK
...

Sheet Property Listing by LE
B3: Property Listing by Legal Entity as at 8 March 2025
B4: Legal Entity | C4: Property | D4: Property Name | E4: Property Address | F4: City | G4: County | H4: PostCode | I4: Units | J4: TAX Authority | K4: TAX Point | L4: Currency | M4: Rate Provider | N4: Primary Contact | O4: Phone | P4: E-mail | Q4: Contact Role | R4: Contact Company Name | S4: Contact Address | T4: Contact City | U4: County | V4: PostCode
B5: o001
B6: o001 | C6: c001 | D6: Canary Wharf Limited | J6: uk | K6: Invoice | L6: gbp | M6: blo(spot)
B7: o001 | C7: p112 | D7: Westferry Pier - Co. 01 | I7: 1120T020, 112OT010 | J7: uk | K7: Invoice | L7: gbp | M7: blo(spot)
B8: o001 | C8: p115 | D8: Cabot Square Watercourts Retail - Co. 01 (17303) | I8: 11500010, 11500020, 11500030, 115OS010, 115OS015, 115OS050, 115OTH10, 115OTH20, 115OTH30, 115OTH40, 115ST010 | J8: uk | K8: Invoice | L8: gbp | M8: blo(spot)
B9: o001 | C9: p141 | D9: 20 Colombus Court Yard - Co. 01 (B5 27001) | E9: 20 Columbus Courtyard | F9: London | H9: E14 4DA | I9: 14100010, 141OT010, 141P1010, 141P1020, 141P1030, 141P1095 | J9: uk | K9: Invoice | L9: gbp | M9: blo(spot)
B10: o001 | C10: p152 | D10: 8 Canada Square Office - Co. 01 (DS2 42001) | E10: 8 - 14 Canada Square | F10: London | H10: E14 5HQ | I10: 15200010, 152OT010 | J10: uk | K10: Invoice | L10: gbp | M10: blo(spot)
B11: o001 | C11: p155 | D11: 20 Canada Square Office - Co. 01 (DS4 44001) | E11: 20 Canada Square | F11: London | H11: E14 5NN | I11: 15500008, 15500010, 15500020, 15500030, 15500040, 15500050, 1550006A, 15500070, 15500100, 15501010, 15502010, 15503010, 15504010, 15505010, 15505020, 15505030, 15505040, 15506010, 15506020, 15507010, 15508010, 15509010, 15510010, 15511010, 15512010, 155B1010, 155B1020, 155ECC01, 155ECC02, 155ECC03, 155OT010, 155P1001, 155P1002, 155P1003, 155P1004, 155P1005, 155P1006, 155P1007, 155P1008, 155P1009, 155P1010, 155P1011, 155P1012, 155P1013, 155P1014, 155P1015, 155P1016, 155P1017, 155P1018, 155P1019, 155P1020, 155P1021, 155P1022, 155PR010, 155ST010, 155ST020, 155ST030, 155ST040, 155ST050, 155ST060, 155ST070, 155ST080, 155ST090, 155ST100, 155ST110 | J11: uk | K11: Invoice | L11: gbp | M11: blo(spot)
B12: o001 | C12: p163 | D12: 25 Churchill Place - Co. 01 (BP4 54001) | E12: 25 Churchill Place | F12: London | H12: E14 5RE | I12: 16301010, 16302010, 16303010, 16304010, 16305010, 16306010, 16307010, 16308010, 16309010, 16310010, 16311010, 16313010, 16314010, 16315010, 16316010, 16317010, 16318010, 16319010, 16320010, 16321010, 16322010, 163ENE10, 163GR010, 163GR020, 163PR010, 163ST010, 163ST020 | J12: uk | K12: Invoice | L12: gbp | M12: blo(spot)
B13: o001 | C13: p231 | D13: OLD - Reuters Plaza Kiosk - Co. 01 (Nash Court 16002) | E13: Reuters Plaza | F13: London | I13: 231000K1, 231000K2, 231000K3, 231000K4, 231000K5, 23100K2A, 231OS0K5, 231OTH10 | J13: uk | K13: Invoice | L13: gbp | M13: blo(spot)
B14: o001 | C14: p246 | D14: Kiosk 20 and Pontoon - Co. 01 (WW) | E14: 22 Churchill Place | F14: London | H14: E14 | I14: 24600010 | J14: uk | K14: Invoice | L14: gbp | M14: blo(spot) | Q14: Leasing Administration
B15: o001 | C15: p300 | D15: 8 Canada Square Retail - Co. 01 (DS2 42001) | E15: 8 - 14 Canada Square | F15: London | H15: E14 5HQ | J15: uk | K15: Invoice | L15: gbp | M15: blo(spot)
B16: o001 | C16: p301 | D16: 20 Canada Square Retail - Co. 01 (DS4 44001) | E16: 20 Canada Square | F16: London | H16: E14 5NN | J16: uk | K16: Invoice | L16: gbp | M16: blo(spot)
